Waiting for all LocalStack services to be ready
2020-02-13 21:20:57,408 CRIT Supervisor is running as root.  Privileges were not dropped because no user is specified in the config file.  If you intend to run as root, you can set user=root in the config file to avoid this message.
2020-02-13 21:20:57,410 INFO supervisord started with pid 13
2020-02-13 21:20:58,414 INFO spawned: 'dashboard' with pid 19
2020-02-13 21:20:58,418 INFO spawned: 'infra' with pid 20
2020-02-13 21:20:58,423 INFO success: dashboard entered RUNNING state, process has stayed up for > than 0 seconds (startsecs)
(. .venv/bin/activate; bin/localstack web)
(. .venv/bin/activate; exec bin/localstack start --host)
Starting local dev environment. CTRL-C to quit.
2020-02-13 21:20:59,747 INFO success: infra entered RUNNING state, process has stayed up for > than 1 seconds (startsecs)
Waiting for all LocalStack services to be ready
2020-02-13T21:21:05:INFO:localstack.services.install: Downloading and installing local KMS server. This may take some time.
Waiting for all LocalStack services to be ready
Waiting for all LocalStack services to be ready
Starting mock API Gateway (http port 4567)...
2020-02-13T21:21:20:INFO:localstack.multiserver: Starting multi API server process on port 51492
Starting mock CloudFormation (http port 4581)...
Starting mock CloudWatch (http port 4582)...
Starting mock DynamoDB (http port 4569)...
Starting mock DynamoDB Streams service (http port 4570)...
Starting mock EC2 (http port 4597)...
Starting mock ES service (http port 4578)...
Starting mock CloudWatch Events (http port 4587)...
Starting mock Firehose service (http port 4573)...
Starting mock IAM (http port 4593)...
Starting mock Kinesis (http port 4568)...
Starting mock KMS (http port 4599)...
Starting mock Lambda service (http port 4574)...
Starting mock CloudWatch Logs (http port 4586)...
Starting mock Redshift (http port 4577)...
Starting mock Route53 (http port 4580)...
Starting mock S3 (http port 4572)...
Starting mock Secrets Manager (http port 4584)...
Starting mock SES (http port 4579)...
Starting mock SNS (http port 4575)...
Starting mock SQS (http port 4576)...
Starting mock SSM (http port 4583)...
Starting mock STS (http port 4592)...
Starting mock StepFunctions (http port 4585)...
2020-02-13T21:21:22:ERROR:localstack.services.generic_proxy: Error forwarding request: MyHTTPConnectionPool(host='localhost', port=4563): Max retries exceeded with url: /invoice-local-serverlessdeploymentbucket-efo44cvdpmio?location (Caused by NewConnectionError('<urllib3.connection.HTTPConnection object at 0x7febf7845890>: Failed to establish a new connection: [Errno 111] Connection refused')) Traceback (most recent call last):
  File "/opt/code/localstack/.venv/lib/python3.7/site-packages/urllib3/connection.py", line 157, in _new_conn
    (self._dns_host, self.port), self.timeout, **extra_kw
  File "/opt/code/localstack/.venv/lib/python3.7/site-packages/urllib3/util/connection.py", line 84, in create_connection
    raise err
  File "/opt/code/localstack/.venv/lib/python3.7/site-packages/urllib3/util/connection.py", line 74, in create_connection
    sock.connect(sa)
ConnectionRefusedError: [Errno 111] Connection refused

During handling of the above exception, another exception occurred:

Traceback (most recent call last):
  File "/opt/code/localstack/.venv/lib/python3.7/site-packages/urllib3/connectionpool.py", line 672, in urlopen
    chunked=chunked,
  File "/opt/code/localstack/.venv/lib/python3.7/site-packages/urllib3/connectionpool.py", line 387, in _make_request
    conn.request(method, url, **httplib_request_kw)
  File "/usr/lib/python3.7/http/client.py", line 1252, in request
    self._send_request(method, url, body, headers, encode_chunked)
  File "/usr/lib/python3.7/http/client.py", line 1298, in _send_request
    self.endheaders(body, encode_chunked=encode_chunked)
  File "/usr/lib/python3.7/http/client.py", line 1247, in endheaders
    self._send_output(message_body, encode_chunked=encode_chunked)
  File "/usr/lib/python3.7/http/client.py", line 1026, in _send_output
    self.send(msg)
  File "/usr/lib/python3.7/http/client.py", line 966, in send
    self.connect()
  File "/opt/code/localstack/.venv/lib/python3.7/site-packages/urllib3/connection.py", line 184, in connect
    conn = self._new_conn()
  File "/opt/code/localstack/.venv/lib/python3.7/site-packages/urllib3/connection.py", line 169, in _new_conn
    self, "Failed to establish a new connection: %s" % e
urllib3.exceptions.NewConnectionError: <urllib3.connection.HTTPConnection object at 0x7febf7845890>: Failed to establish a new connection: [Errno 111] Connection refused

During handling of the above exception, another exception occurred:

Traceback (most recent call last):
  File "/opt/code/localstack/.venv/lib/python3.7/site-packages/requests/adapters.py", line 449, in send
    timeout=timeout
  File "/opt/code/localstack/.venv/lib/python3.7/site-packages/urllib3/connectionpool.py", line 720, in urlopen
    method, url, error=e, _pool=self, _stacktrace=sys.exc_info()[2]
  File "/opt/code/localstack/.venv/lib/python3.7/site-packages/urllib3/util/retry.py", line 436, in increment
    raise MaxRetryError(_pool, url, error or ResponseError(cause))
urllib3.exceptions.MaxRetryError: MyHTTPConnectionPool(host='localhost', port=4563): Max retries exceeded with url: /invoice-local-serverlessdeploymentbucket-efo44cvdpmio?location (Caused by NewConnectionError('<urllib3.connection.HTTPConnection object at 0x7febf7845890>: Failed to establish a new connection: [Errno 111] Connection refused'))

During handling of the above exception, another exception occurred:

Traceback (most recent call last):
  File "/opt/code/localstack/localstack/services/generic_proxy.py", line 284, in forward
    headers=forward_headers, stream=True)
  File "/opt/code/localstack/.venv/lib/python3.7/site-packages/requests/api.py", line 75, in get
    return request('get', url, params=params, **kwargs)
  File "/opt/code/localstack/.venv/lib/python3.7/site-packages/requests/api.py", line 60, in request
    return session.request(method=method, url=url, **kwargs)
  File "/opt/code/localstack/.venv/lib/python3.7/site-packages/requests/sessions.py", line 533, in request
    resp = self.send(prep, **send_kwargs)
  File "/opt/code/localstack/.venv/lib/python3.7/site-packages/requests/sessions.py", line 646, in send
    r = adapter.send(request, **kwargs)
  File "/opt/code/localstack/.venv/lib/python3.7/site-packages/requests/adapters.py", line 516, in send
    raise ConnectionError(e, request=request)
requests.exceptions.ConnectionError: MyHTTPConnectionPool(host='localhost', port=4563): Max retries exceeded with url: /invoice-local-serverlessdeploymentbucket-efo44cvdpmio?location (Caused by NewConnectionError('<urllib3.connection.HTTPConnection object at 0x7febf7845890>: Failed to establish a new connection: [Errno 111] Connection refused'))

2020-02-13T21:21:22:ERROR:localstack.services.generic_proxy: Error forwarding request: MyHTTPConnectionPool(host='localhost', port=4563): Max retries exceeded with url: /invoice-local-serverlessdeploymentbucket-efo44cvdpmio?location (Caused by NewConnectionError('<urllib3.connection.HTTPConnection object at 0x7febf6e116d0>: Failed to establish a new connection: [Errno 111] Connection refused')) Traceback (most recent call last):
  File "/opt/code/localstack/.venv/lib/python3.7/site-packages/urllib3/connection.py", line 157, in _new_conn
    (self._dns_host, self.port), self.timeout, **extra_kw
  File "/opt/code/localstack/.venv/lib/python3.7/site-packages/urllib3/util/connection.py", line 84, in create_connection
    raise err
  File "/opt/code/localstack/.venv/lib/python3.7/site-packages/urllib3/util/connection.py", line 74, in create_connection
    sock.connect(sa)
ConnectionRefusedError: [Errno 111] Connection refused

During handling of the above exception, another exception occurred:

Traceback (most recent call last):
  File "/opt/code/localstack/.venv/lib/python3.7/site-packages/urllib3/connectionpool.py", line 672, in urlopen
    chunked=chunked,
  File "/opt/code/localstack/.venv/lib/python3.7/site-packages/urllib3/connectionpool.py", line 387, in _make_request
    conn.request(method, url, **httplib_request_kw)
  File "/usr/lib/python3.7/http/client.py", line 1252, in request
    self._send_request(method, url, body, headers, encode_chunked)
  File "/usr/lib/python3.7/http/client.py", line 1298, in _send_request
    self.endheaders(body, encode_chunked=encode_chunked)
  File "/usr/lib/python3.7/http/client.py", line 1247, in endheaders
    self._send_output(message_body, encode_chunked=encode_chunked)
  File "/usr/lib/python3.7/http/client.py", line 1026, in _send_output
    self.send(msg)
  File "/usr/lib/python3.7/http/client.py", line 966, in send
    self.connect()
  File "/opt/code/localstack/.venv/lib/python3.7/site-packages/urllib3/connection.py", line 184, in connect
    conn = self._new_conn()
  File "/opt/code/localstack/.venv/lib/python3.7/site-packages/urllib3/connection.py", line 169, in _new_conn
    self, "Failed to establish a new connection: %s" % e
urllib3.exceptions.NewConnectionError: <urllib3.connection.HTTPConnection object at 0x7febf6e116d0>: Failed to establish a new connection: [Errno 111] Connection refused

During handling of the above exception, another exception occurred:

Traceback (most recent call last):
  File "/opt/code/localstack/.venv/lib/python3.7/site-packages/requests/adapters.py", line 449, in send
    timeout=timeout
  File "/opt/code/localstack/.venv/lib/python3.7/site-packages/urllib3/connectionpool.py", line 720, in urlopen
    method, url, error=e, _pool=self, _stacktrace=sys.exc_info()[2]
  File "/opt/code/localstack/.venv/lib/python3.7/site-packages/urllib3/util/retry.py", line 436, in increment
    raise MaxRetryError(_pool, url, error or ResponseError(cause))
urllib3.exceptions.MaxRetryError: MyHTTPConnectionPool(host='localhost', port=4563): Max retries exceeded with url: /invoice-local-serverlessdeploymentbucket-efo44cvdpmio?location (Caused by NewConnectionError('<urllib3.connection.HTTPConnection object at 0x7febf6e116d0>: Failed to establish a new connection: [Errno 111] Connection refused'))

During handling of the above exception, another exception occurred:

Traceback (most recent call last):
  File "/opt/code/localstack/localstack/services/generic_proxy.py", line 284, in forward
    headers=forward_headers, stream=True)
  File "/opt/code/localstack/.venv/lib/python3.7/site-packages/requests/api.py", line 75, in get
    return request('get', url, params=params, **kwargs)
  File "/opt/code/localstack/.venv/lib/python3.7/site-packages/requests/api.py", line 60, in request
    return session.request(method=method, url=url, **kwargs)
  File "/opt/code/localstack/.venv/lib/python3.7/site-packages/requests/sessions.py", line 533, in request
    resp = self.send(prep, **send_kwargs)
  File "/opt/code/localstack/.venv/lib/python3.7/site-packages/requests/sessions.py", line 646, in send
    r = adapter.send(request, **kwargs)
  File "/opt/code/localstack/.venv/lib/python3.7/site-packages/requests/adapters.py", line 516, in send
    raise ConnectionError(e, request=request)
requests.exceptions.ConnectionError: MyHTTPConnectionPool(host='localhost', port=4563): Max retries exceeded with url: /invoice-local-serverlessdeploymentbucket-efo44cvdpmio?location (Caused by NewConnectionError('<urllib3.connection.HTTPConnection object at 0x7febf6e116d0>: Failed to establish a new connection: [Errno 111] Connection refused'))

2020-02-13T21:21:23:ERROR:localstack.services.generic_proxy: Error forwarding request: MyHTTPConnectionPool(host='localhost', port=4563): Max retries exceeded with url: /invoice-local-serverlessdeploymentbucket-efo44cvdpmio?location (Caused by NewConnectionError('<urllib3.connection.HTTPConnection object at 0x7febf6b3d090>: Failed to establish a new connection: [Errno 111] Connection refused')) Traceback (most recent call last):
  File "/opt/code/localstack/.venv/lib/python3.7/site-packages/urllib3/connection.py", line 157, in _new_conn
    (self._dns_host, self.port), self.timeout, **extra_kw
  File "/opt/code/localstack/.venv/lib/python3.7/site-packages/urllib3/util/connection.py", line 84, in create_connection
    raise err
  File "/opt/code/localstack/.venv/lib/python3.7/site-packages/urllib3/util/connection.py", line 74, in create_connection
    sock.connect(sa)
ConnectionRefusedError: [Errno 111] Connection refused

During handling of the above exception, another exception occurred:

Traceback (most recent call last):
  File "/opt/code/localstack/.venv/lib/python3.7/site-packages/urllib3/connectionpool.py", line 672, in urlopen
    chunked=chunked,
  File "/opt/code/localstack/.venv/lib/python3.7/site-packages/urllib3/connectionpool.py", line 387, in _make_request
    conn.request(method, url, **httplib_request_kw)
  File "/usr/lib/python3.7/http/client.py", line 1252, in request
    self._send_request(method, url, body, headers, encode_chunked)
  File "/usr/lib/python3.7/http/client.py", line 1298, in _send_request
    self.endheaders(body, encode_chunked=encode_chunked)
  File "/usr/lib/python3.7/http/client.py", line 1247, in endheaders
    self._send_output(message_body, encode_chunked=encode_chunked)
  File "/usr/lib/python3.7/http/client.py", line 1026, in _send_output
    self.send(msg)
  File "/usr/lib/python3.7/http/client.py", line 966, in send
    self.connect()
  File "/opt/code/localstack/.venv/lib/python3.7/site-packages/urllib3/connection.py", line 184, in connect
    conn = self._new_conn()
  File "/opt/code/localstack/.venv/lib/python3.7/site-packages/urllib3/connection.py", line 169, in _new_conn
    self, "Failed to establish a new connection: %s" % e
urllib3.exceptions.NewConnectionError: <urllib3.connection.HTTPConnection object at 0x7febf6b3d090>: Failed to establish a new connection: [Errno 111] Connection refused

During handling of the above exception, another exception occurred:

Traceback (most recent call last):
  File "/opt/code/localstack/.venv/lib/python3.7/site-packages/requests/adapters.py", line 449, in send
    timeout=timeout
  File "/opt/code/localstack/.venv/lib/python3.7/site-packages/urllib3/connectionpool.py", line 720, in urlopen
    method, url, error=e, _pool=self, _stacktrace=sys.exc_info()[2]
  File "/opt/code/localstack/.venv/lib/python3.7/site-packages/urllib3/util/retry.py", line 436, in increment
    raise MaxRetryError(_pool, url, error or ResponseError(cause))
urllib3.exceptions.MaxRetryError: MyHTTPConnectionPool(host='localhost', port=4563): Max retries exceeded with url: /invoice-local-serverlessdeploymentbucket-efo44cvdpmio?location (Caused by NewConnectionError('<urllib3.connection.HTTPConnection object at 0x7febf6b3d090>: Failed to establish a new connection: [Errno 111] Connection refused'))

During handling of the above exception, another exception occurred:

Traceback (most recent call last):
  File "/opt/code/localstack/localstack/services/generic_proxy.py", line 284, in forward
    headers=forward_headers, stream=True)
  File "/opt/code/localstack/.venv/lib/python3.7/site-packages/requests/api.py", line 75, in get
    return request('get', url, params=params, **kwargs)
  File "/opt/code/localstack/.venv/lib/python3.7/site-packages/requests/api.py", line 60, in request
    return session.request(method=method, url=url, **kwargs)
  File "/opt/code/localstack/.venv/lib/python3.7/site-packages/requests/sessions.py", line 533, in request
    resp = self.send(prep, **send_kwargs)
  File "/opt/code/localstack/.venv/lib/python3.7/site-packages/requests/sessions.py", line 646, in send
    r = adapter.send(request, **kwargs)
  File "/opt/code/localstack/.venv/lib/python3.7/site-packages/requests/adapters.py", line 516, in send
    raise ConnectionError(e, request=request)
requests.exceptions.ConnectionError: MyHTTPConnectionPool(host='localhost', port=4563): Max retries exceeded with url: /invoice-local-serverlessdeploymentbucket-efo44cvdpmio?location (Caused by NewConnectionError('<urllib3.connection.HTTPConnection object at 0x7febf6b3d090>: Failed to establish a new connection: [Errno 111] Connection refused'))

2020-02-13T21:21:23:ERROR:localstack.services.generic_proxy: Error forwarding request: MyHTTPConnectionPool(host='localhost', port=4563): Max retries exceeded with url: /invoice-local-serverlessdeploymentbucket-efo44cvdpmio?location (Caused by NewConnectionError('<urllib3.connection.HTTPConnection object at 0x7febf6e08ed0>: Failed to establish a new connection: [Errno 111] Connection refused')) Traceback (most recent call last):
  File "/opt/code/localstack/.venv/lib/python3.7/site-packages/urllib3/connection.py", line 157, in _new_conn
    (self._dns_host, self.port), self.timeout, **extra_kw
  File "/opt/code/localstack/.venv/lib/python3.7/site-packages/urllib3/util/connection.py", line 84, in create_connection
    raise err
  File "/opt/code/localstack/.venv/lib/python3.7/site-packages/urllib3/util/connection.py", line 74, in create_connection
    sock.connect(sa)
ConnectionRefusedError: [Errno 111] Connection refused

During handling of the above exception, another exception occurred:

Traceback (most recent call last):
  File "/opt/code/localstack/.venv/lib/python3.7/site-packages/urllib3/connectionpool.py", line 672, in urlopen
    chunked=chunked,
  File "/opt/code/localstack/.venv/lib/python3.7/site-packages/urllib3/connectionpool.py", line 387, in _make_request
    conn.request(method, url, **httplib_request_kw)
  File "/usr/lib/python3.7/http/client.py", line 1252, in request
    self._send_request(method, url, body, headers, encode_chunked)
  File "/usr/lib/python3.7/http/client.py", line 1298, in _send_request
    self.endheaders(body, encode_chunked=encode_chunked)
  File "/usr/lib/python3.7/http/client.py", line 1247, in endheaders
    self._send_output(message_body, encode_chunked=encode_chunked)
  File "/usr/lib/python3.7/http/client.py", line 1026, in _send_output
    self.send(msg)
  File "/usr/lib/python3.7/http/client.py", line 966, in send
    self.connect()
  File "/opt/code/localstack/.venv/lib/python3.7/site-packages/urllib3/connection.py", line 184, in connect
    conn = self._new_conn()
  File "/opt/code/localstack/.venv/lib/python3.7/site-packages/urllib3/connection.py", line 169, in _new_conn
    self, "Failed to establish a new connection: %s" % e
urllib3.exceptions.NewConnectionError: <urllib3.connection.HTTPConnection object at 0x7febf6e08ed0>: Failed to establish a new connection: [Errno 111] Connection refused

During handling of the above exception, another exception occurred:

Traceback (most recent call last):
  File "/opt/code/localstack/.venv/lib/python3.7/site-packages/requests/adapters.py", line 449, in send
    timeout=timeout
  File "/opt/code/localstack/.venv/lib/python3.7/site-packages/urllib3/connectionpool.py", line 720, in urlopen
    method, url, error=e, _pool=self, _stacktrace=sys.exc_info()[2]
  File "/opt/code/localstack/.venv/lib/python3.7/site-packages/urllib3/util/retry.py", line 436, in increment
    raise MaxRetryError(_pool, url, error or ResponseError(cause))
urllib3.exceptions.MaxRetryError: MyHTTPConnectionPool(host='localhost', port=4563): Max retries exceeded with url: /invoice-local-serverlessdeploymentbucket-efo44cvdpmio?location (Caused by NewConnectionError('<urllib3.connection.HTTPConnection object at 0x7febf6e08ed0>: Failed to establish a new connection: [Errno 111] Connection refused'))

During handling of the above exception, another exception occurred:

Traceback (most recent call last):
  File "/opt/code/localstack/localstack/services/generic_proxy.py", line 284, in forward
    headers=forward_headers, stream=True)
  File "/opt/code/localstack/.venv/lib/python3.7/site-packages/requests/api.py", line 75, in get
    return request('get', url, params=params, **kwargs)
  File "/opt/code/localstack/.venv/lib/python3.7/site-packages/requests/api.py", line 60, in request
    return session.request(method=method, url=url, **kwargs)
  File "/opt/code/localstack/.venv/lib/python3.7/site-packages/requests/sessions.py", line 533, in request
    resp = self.send(prep, **send_kwargs)
  File "/opt/code/localstack/.venv/lib/python3.7/site-packages/requests/sessions.py", line 646, in send
    r = adapter.send(request, **kwargs)
  File "/opt/code/localstack/.venv/lib/python3.7/site-packages/requests/adapters.py", line 516, in send
    raise ConnectionError(e, request=request)
requests.exceptions.ConnectionError: MyHTTPConnectionPool(host='localhost', port=4563): Max retries exceeded with url: /invoice-local-serverlessdeploymentbucket-efo44cvdpmio?location (Caused by NewConnectionError('<urllib3.connection.HTTPConnection object at 0x7febf6e08ed0>: Failed to establish a new connection: [Errno 111] Connection refused'))

Waiting for all LocalStack services to be ready
2020-02-13T21:21:28:ERROR:localstack.services.generic_proxy: Error forwarding request: MyHTTPConnectionPool(host='localhost', port=4563): Max retries exceeded with url: /user-local-serverlessdeploymentbucket-7sai580wxc84?location (Caused by NewConnectionError('<urllib3.connection.HTTPConnection object at 0x7febf731b090>: Failed to establish a new connection: [Errno 111] Connection refused')) Traceback (most recent call last):
  File "/opt/code/localstack/.venv/lib/python3.7/site-packages/urllib3/connection.py", line 157, in _new_conn
    (self._dns_host, self.port), self.timeout, **extra_kw
  File "/opt/code/localstack/.venv/lib/python3.7/site-packages/urllib3/util/connection.py", line 84, in create_connection
    raise err
  File "/opt/code/localstack/.venv/lib/python3.7/site-packages/urllib3/util/connection.py", line 74, in create_connection
    sock.connect(sa)
ConnectionRefusedError: [Errno 111] Connection refused

During handling of the above exception, another exception occurred:

Traceback (most recent call last):
  File "/opt/code/localstack/.venv/lib/python3.7/site-packages/urllib3/connectionpool.py", line 672, in urlopen
    chunked=chunked,
  File "/opt/code/localstack/.venv/lib/python3.7/site-packages/urllib3/connectionpool.py", line 387, in _make_request
    conn.request(method, url, **httplib_request_kw)
  File "/usr/lib/python3.7/http/client.py", line 1252, in request
    self._send_request(method, url, body, headers, encode_chunked)
  File "/usr/lib/python3.7/http/client.py", line 1298, in _send_request
    self.endheaders(body, encode_chunked=encode_chunked)
  File "/usr/lib/python3.7/http/client.py", line 1247, in endheaders
    self._send_output(message_body, encode_chunked=encode_chunked)
  File "/usr/lib/python3.7/http/client.py", line 1026, in _send_output
    self.send(msg)
  File "/usr/lib/python3.7/http/client.py", line 966, in send
    self.connect()
  File "/opt/code/localstack/.venv/lib/python3.7/site-packages/urllib3/connection.py", line 184, in connect
    conn = self._new_conn()
  File "/opt/code/localstack/.venv/lib/python3.7/site-packages/urllib3/connection.py", line 169, in _new_conn
    self, "Failed to establish a new connection: %s" % e
urllib3.exceptions.NewConnectionError: <urllib3.connection.HTTPConnection object at 0x7febf731b090>: Failed to establish a new connection: [Errno 111] Connection refused

During handling of the above exception, another exception occurred:

Traceback (most recent call last):
  File "/opt/code/localstack/.venv/lib/python3.7/site-packages/requests/adapters.py", line 449, in send
    timeout=timeout
  File "/opt/code/localstack/.venv/lib/python3.7/site-packages/urllib3/connectionpool.py", line 720, in urlopen
    method, url, error=e, _pool=self, _stacktrace=sys.exc_info()[2]
  File "/opt/code/localstack/.venv/lib/python3.7/site-packages/urllib3/util/retry.py", line 436, in increment
    raise MaxRetryError(_pool, url, error or ResponseError(cause))
urllib3.exceptions.MaxRetryError: MyHTTPConnectionPool(host='localhost', port=4563): Max retries exceeded with url: /user-local-serverlessdeploymentbucket-7sai580wxc84?location (Caused by NewConnectionError('<urllib3.connection.HTTPConnection object at 0x7febf731b090>: Failed to establish a new connection: [Errno 111] Connection refused'))

During handling of the above exception, another exception occurred:

Traceback (most recent call last):
  File "/opt/code/localstack/localstack/services/generic_proxy.py", line 284, in forward
    headers=forward_headers, stream=True)
  File "/opt/code/localstack/.venv/lib/python3.7/site-packages/requests/api.py", line 75, in get
    return request('get', url, params=params, **kwargs)
  File "/opt/code/localstack/.venv/lib/python3.7/site-packages/requests/api.py", line 60, in request
    return session.request(method=method, url=url, **kwargs)
  File "/opt/code/localstack/.venv/lib/python3.7/site-packages/requests/sessions.py", line 533, in request
    resp = self.send(prep, **send_kwargs)
  File "/opt/code/localstack/.venv/lib/python3.7/site-packages/requests/sessions.py", line 646, in send
    r = adapter.send(request, **kwargs)
  File "/opt/code/localstack/.venv/lib/python3.7/site-packages/requests/adapters.py", line 516, in send
    raise ConnectionError(e, request=request)
requests.exceptions.ConnectionError: MyHTTPConnectionPool(host='localhost', port=4563): Max retries exceeded with url: /user-local-serverlessdeploymentbucket-7sai580wxc84?location (Caused by NewConnectionError('<urllib3.connection.HTTPConnection object at 0x7febf731b090>: Failed to establish a new connection: [Errno 111] Connection refused'))

2020-02-13T21:21:28:ERROR:localstack.services.generic_proxy: Error forwarding request: MyHTTPConnectionPool(host='localhost', port=4563): Max retries exceeded with url: /user-local-serverlessdeploymentbucket-7sai580wxc84?location (Caused by NewConnectionError('<urllib3.connection.HTTPConnection object at 0x7febf730e410>: Failed to establish a new connection: [Errno 111] Connection refused')) Traceback (most recent call last):
  File "/opt/code/localstack/.venv/lib/python3.7/site-packages/urllib3/connection.py", line 157, in _new_conn
    (self._dns_host, self.port), self.timeout, **extra_kw
  File "/opt/code/localstack/.venv/lib/python3.7/site-packages/urllib3/util/connection.py", line 84, in create_connection
    raise err
  File "/opt/code/localstack/.venv/lib/python3.7/site-packages/urllib3/util/connection.py", line 74, in create_connection
    sock.connect(sa)
ConnectionRefusedError: [Errno 111] Connection refused

During handling of the above exception, another exception occurred:

Traceback (most recent call last):
  File "/opt/code/localstack/.venv/lib/python3.7/site-packages/urllib3/connectionpool.py", line 672, in urlopen
    chunked=chunked,
  File "/opt/code/localstack/.venv/lib/python3.7/site-packages/urllib3/connectionpool.py", line 387, in _make_request
    conn.request(method, url, **httplib_request_kw)
  File "/usr/lib/python3.7/http/client.py", line 1252, in request
    self._send_request(method, url, body, headers, encode_chunked)
  File "/usr/lib/python3.7/http/client.py", line 1298, in _send_request
    self.endheaders(body, encode_chunked=encode_chunked)
  File "/usr/lib/python3.7/http/client.py", line 1247, in endheaders
    self._send_output(message_body, encode_chunked=encode_chunked)
  File "/usr/lib/python3.7/http/client.py", line 1026, in _send_output
    self.send(msg)
  File "/usr/lib/python3.7/http/client.py", line 966, in send
    self.connect()
  File "/opt/code/localstack/.venv/lib/python3.7/site-packages/urllib3/connection.py", line 184, in connect
    conn = self._new_conn()
  File "/opt/code/localstack/.venv/lib/python3.7/site-packages/urllib3/connection.py", line 169, in _new_conn
    self, "Failed to establish a new connection: %s" % e
urllib3.exceptions.NewConnectionError: <urllib3.connection.HTTPConnection object at 0x7febf730e410>: Failed to establish a new connection: [Errno 111] Connection refused

During handling of the above exception, another exception occurred:

Traceback (most recent call last):
  File "/opt/code/localstack/.venv/lib/python3.7/site-packages/requests/adapters.py", line 449, in send
    timeout=timeout
  File "/opt/code/localstack/.venv/lib/python3.7/site-packages/urllib3/connectionpool.py", line 720, in urlopen
    method, url, error=e, _pool=self, _stacktrace=sys.exc_info()[2]
  File "/opt/code/localstack/.venv/lib/python3.7/site-packages/urllib3/util/retry.py", line 436, in increment
    raise MaxRetryError(_pool, url, error or ResponseError(cause))
urllib3.exceptions.MaxRetryError: MyHTTPConnectionPool(host='localhost', port=4563): Max retries exceeded with url: /user-local-serverlessdeploymentbucket-7sai580wxc84?location (Caused by NewConnectionError('<urllib3.connection.HTTPConnection object at 0x7febf730e410>: Failed to establish a new connection: [Errno 111] Connection refused'))

During handling of the above exception, another exception occurred:

Traceback (most recent call last):
  File "/opt/code/localstack/localstack/services/generic_proxy.py", line 284, in forward
    headers=forward_headers, stream=True)
  File "/opt/code/localstack/.venv/lib/python3.7/site-packages/requests/api.py", line 75, in get
    return request('get', url, params=params, **kwargs)
  File "/opt/code/localstack/.venv/lib/python3.7/site-packages/requests/api.py", line 60, in request
    return session.request(method=method, url=url, **kwargs)
  File "/opt/code/localstack/.venv/lib/python3.7/site-packages/requests/sessions.py", line 533, in request
    resp = self.send(prep, **send_kwargs)
  File "/opt/code/localstack/.venv/lib/python3.7/site-packages/requests/sessions.py", line 646, in send
    r = adapter.send(request, **kwargs)
  File "/opt/code/localstack/.venv/lib/python3.7/site-packages/requests/adapters.py", line 516, in send
    raise ConnectionError(e, request=request)
requests.exceptions.ConnectionError: MyHTTPConnectionPool(host='localhost', port=4563): Max retries exceeded with url: /user-local-serverlessdeploymentbucket-7sai580wxc84?location (Caused by NewConnectionError('<urllib3.connection.HTTPConnection object at 0x7febf730e410>: Failed to establish a new connection: [Errno 111] Connection refused'))

2020-02-13T21:21:28:ERROR:localstack.services.generic_proxy: Error forwarding request: MyHTTPConnectionPool(host='localhost', port=4563): Max retries exceeded with url: /invoice-local-serverlessdeploymentbucket-efo44cvdpmio?location (Caused by NewConnectionError('<urllib3.connection.HTTPConnection object at 0x7febf7311290>: Failed to establish a new connection: [Errno 111] Connection refused')) Traceback (most recent call last):
  File "/opt/code/localstack/.venv/lib/python3.7/site-packages/urllib3/connection.py", line 157, in _new_conn
    (self._dns_host, self.port), self.timeout, **extra_kw
  File "/opt/code/localstack/.venv/lib/python3.7/site-packages/urllib3/util/connection.py", line 84, in create_connection
    raise err
  File "/opt/code/localstack/.venv/lib/python3.7/site-packages/urllib3/util/connection.py", line 74, in create_connection
    sock.connect(sa)
ConnectionRefusedError: [Errno 111] Connection refused

During handling of the above exception, another exception occurred:

Traceback (most recent call last):
  File "/opt/code/localstack/.venv/lib/python3.7/site-packages/urllib3/connectionpool.py", line 672, in urlopen
    chunked=chunked,
  File "/opt/code/localstack/.venv/lib/python3.7/site-packages/urllib3/connectionpool.py", line 387, in _make_request
    conn.request(method, url, **httplib_request_kw)
  File "/usr/lib/python3.7/http/client.py", line 1252, in request
    self._send_request(method, url, body, headers, encode_chunked)
  File "/usr/lib/python3.7/http/client.py", line 1298, in _send_request
    self.endheaders(body, encode_chunked=encode_chunked)
  File "/usr/lib/python3.7/http/client.py", line 1247, in endheaders
    self._send_output(message_body, encode_chunked=encode_chunked)
  File "/usr/lib/python3.7/http/client.py", line 1026, in _send_output
    self.send(msg)
  File "/usr/lib/python3.7/http/client.py", line 966, in send
    self.connect()
  File "/opt/code/localstack/.venv/lib/python3.7/site-packages/urllib3/connection.py", line 184, in connect
    conn = self._new_conn()
  File "/opt/code/localstack/.venv/lib/python3.7/site-packages/urllib3/connection.py", line 169, in _new_conn
    self, "Failed to establish a new connection: %s" % e
urllib3.exceptions.NewConnectionError: <urllib3.connection.HTTPConnection object at 0x7febf7311290>: Failed to establish a new connection: [Errno 111] Connection refused

During handling of the above exception, another exception occurred:

Traceback (most recent call last):
  File "/opt/code/localstack/.venv/lib/python3.7/site-packages/requests/adapters.py", line 449, in send
    timeout=timeout
  File "/opt/code/localstack/.venv/lib/python3.7/site-packages/urllib3/connectionpool.py", line 720, in urlopen
    method, url, error=e, _pool=self, _stacktrace=sys.exc_info()[2]
  File "/opt/code/localstack/.venv/lib/python3.7/site-packages/urllib3/util/retry.py", line 436, in increment
    raise MaxRetryError(_pool, url, error or ResponseError(cause))
urllib3.exceptions.MaxRetryError: MyHTTPConnectionPool(host='localhost', port=4563): Max retries exceeded with url: /invoice-local-serverlessdeploymentbucket-efo44cvdpmio?location (Caused by NewConnectionError('<urllib3.connection.HTTPConnection object at 0x7febf7311290>: Failed to establish a new connection: [Errno 111] Connection refused'))

During handling of the above exception, another exception occurred:

Traceback (most recent call last):
  File "/opt/code/localstack/localstack/services/generic_proxy.py", line 284, in forward
    headers=forward_headers, stream=True)
  File "/opt/code/localstack/.venv/lib/python3.7/site-packages/requests/api.py", line 75, in get
    return request('get', url, params=params, **kwargs)
  File "/opt/code/localstack/.venv/lib/python3.7/site-packages/requests/api.py", line 60, in request
    return session.request(method=method, url=url, **kwargs)
  File "/opt/code/localstack/.venv/lib/python3.7/site-packages/requests/sessions.py", line 533, in request
    resp = self.send(prep, **send_kwargs)
  File "/opt/code/localstack/.venv/lib/python3.7/site-packages/requests/sessions.py", line 646, in send
    r = adapter.send(request, **kwargs)
  File "/opt/code/localstack/.venv/lib/python3.7/site-packages/requests/adapters.py", line 516, in send
    raise ConnectionError(e, request=request)
requests.exceptions.ConnectionError: MyHTTPConnectionPool(host='localhost', port=4563): Max retries exceeded with url: /invoice-local-serverlessdeploymentbucket-efo44cvdpmio?location (Caused by NewConnectionError('<urllib3.connection.HTTPConnection object at 0x7febf7311290>: Failed to establish a new connection: [Errno 111] Connection refused'))

2020-02-13T21:21:28:WARNING:localstack.utils.cloudformation.template_deployer: Unexpected error retrieving details for resource S3::Bucket: no element found: line 1, column 0 Traceback (most recent call last):
  File "/opt/code/localstack/localstack/utils/cloudformation/template_deployer.py", line 588, in retrieve_resource_details
    return aws_stack.connect_to_service('s3').get_bucket_location(Bucket=bucket_name)
  File "/opt/code/localstack/.venv/lib/python3.7/site-packages/botocore/client.py", line 276, in _api_call
    return self._make_api_call(operation_name, kwargs)
  File "/opt/code/localstack/.venv/lib/python3.7/site-packages/botocore/client.py", line 580, in _make_api_call
    model=operation_model, context=request_context
  File "/opt/code/localstack/.venv/lib/python3.7/site-packages/botocore/hooks.py", line 356, in emit
    return self._emitter.emit(aliased_event_name, **kwargs)
  File "/opt/code/localstack/.venv/lib/python3.7/site-packages/botocore/hooks.py", line 228, in emit
    return self._emit(event_name, kwargs)
  File "/opt/code/localstack/.venv/lib/python3.7/site-packages/botocore/hooks.py", line 211, in _emit
    response = handler(**kwargs)
  File "/opt/code/localstack/.venv/lib/python3.7/site-packages/botocore/handlers.py", line 495, in parse_get_bucket_location
    root = parser.close()
  File "<string>", line None
xml.etree.ElementTree.ParseError: no element found: line 1, column 0
 - {'Type': 'AWS::S3::Bucket', 'Properties': {'BucketEncryption': {'ServerSideEncryptionConfiguration': [{'ServerSideEncryptionByDefault': {'SSEAlgorithm': 'AES256'}}]}, 'BucketName': 'invoice-local-ServerlessDeploymentBucket-EFO44CVDPMIO'}} {}
2020-02-13T21:21:28:ERROR:localstack.services.generic_proxy: Error forwarding request: MyHTTPConnectionPool(host='localhost', port=4563): Max retries exceeded with url: /invoice-local-serverlessdeploymentbucket-efo44cvdpmio (Caused by NewConnectionError('<urllib3.connection.HTTPConnection object at 0x7febf72fbf10>: Failed to establish a new connection: [Errno 111] Connection refused')) Traceback (most recent call last):
  File "/opt/code/localstack/.venv/lib/python3.7/site-packages/urllib3/connection.py", line 157, in _new_conn
    (self._dns_host, self.port), self.timeout, **extra_kw
  File "/opt/code/localstack/.venv/lib/python3.7/site-packages/urllib3/util/connection.py", line 84, in create_connection
    raise err
  File "/opt/code/localstack/.venv/lib/python3.7/site-packages/urllib3/util/connection.py", line 74, in create_connection
    sock.connect(sa)
ConnectionRefusedError: [Errno 111] Connection refused

During handling of the above exception, another exception occurred:

Traceback (most recent call last):
  File "/opt/code/localstack/.venv/lib/python3.7/site-packages/urllib3/connectionpool.py", line 672, in urlopen
    chunked=chunked,
  File "/opt/code/localstack/.venv/lib/python3.7/site-packages/urllib3/connectionpool.py", line 387, in _make_request
    conn.request(method, url, **httplib_request_kw)
  File "/usr/lib/python3.7/http/client.py", line 1252, in request
    self._send_request(method, url, body, headers, encode_chunked)
  File "/usr/lib/python3.7/http/client.py", line 1298, in _send_request
    self.endheaders(body, encode_chunked=encode_chunked)
  File "/usr/lib/python3.7/http/client.py", line 1247, in endheaders
    self._send_output(message_body, encode_chunked=encode_chunked)
  File "/usr/lib/python3.7/http/client.py", line 1026, in _send_output
    self.send(msg)
  File "/usr/lib/python3.7/http/client.py", line 966, in send
    self.connect()
  File "/opt/code/localstack/.venv/lib/python3.7/site-packages/urllib3/connection.py", line 184, in connect
    conn = self._new_conn()
  File "/opt/code/localstack/.venv/lib/python3.7/site-packages/urllib3/connection.py", line 169, in _new_conn
    self, "Failed to establish a new connection: %s" % e
urllib3.exceptions.NewConnectionError: <urllib3.connection.HTTPConnection object at 0x7febf72fbf10>: Failed to establish a new connection: [Errno 111] Connection refused

During handling of the above exception, another exception occurred:

Traceback (most recent call last):
  File "/opt/code/localstack/.venv/lib/python3.7/site-packages/requests/adapters.py", line 449, in send
    timeout=timeout
  File "/opt/code/localstack/.venv/lib/python3.7/site-packages/urllib3/connectionpool.py", line 720, in urlopen
    method, url, error=e, _pool=self, _stacktrace=sys.exc_info()[2]
  File "/opt/code/localstack/.venv/lib/python3.7/site-packages/urllib3/util/retry.py", line 436, in increment
    raise MaxRetryError(_pool, url, error or ResponseError(cause))
urllib3.exceptions.MaxRetryError: MyHTTPConnectionPool(host='localhost', port=4563): Max retries exceeded with url: /invoice-local-serverlessdeploymentbucket-efo44cvdpmio (Caused by NewConnectionError('<urllib3.connection.HTTPConnection object at 0x7febf72fbf10>: Failed to establish a new connection: [Errno 111] Connection refused'))

During handling of the above exception, another exception occurred:

Traceback (most recent call last):
  File "/opt/code/localstack/localstack/services/generic_proxy.py", line 284, in forward
    headers=forward_headers, stream=True)
  File "/opt/code/localstack/.venv/lib/python3.7/site-packages/requests/api.py", line 131, in put
    return request('put', url, data=data, **kwargs)
  File "/opt/code/localstack/.venv/lib/python3.7/site-packages/requests/api.py", line 60, in request
    return session.request(method=method, url=url, **kwargs)
  File "/opt/code/localstack/.venv/lib/python3.7/site-packages/requests/sessions.py", line 533, in request
    resp = self.send(prep, **send_kwargs)
  File "/opt/code/localstack/.venv/lib/python3.7/site-packages/requests/sessions.py", line 646, in send
    r = adapter.send(request, **kwargs)
  File "/opt/code/localstack/.venv/lib/python3.7/site-packages/requests/adapters.py", line 516, in send
    raise ConnectionError(e, request=request)
requests.exceptions.ConnectionError: MyHTTPConnectionPool(host='localhost', port=4563): Max retries exceeded with url: /invoice-local-serverlessdeploymentbucket-efo44cvdpmio (Caused by NewConnectionError('<urllib3.connection.HTTPConnection object at 0x7febf72fbf10>: Failed to establish a new connection: [Errno 111] Connection refused'))

2020-02-13T21:21:29:ERROR:localstack.services.generic_proxy: Error forwarding request: MyHTTPConnectionPool(host='localhost', port=4563): Max retries exceeded with url: /user-local-serverlessdeploymentbucket-7sai580wxc84?location (Caused by NewConnectionError('<urllib3.connection.HTTPConnection object at 0x7febf72f5290>: Failed to establish a new connection: [Errno 111] Connection refused')) Traceback (most recent call last):
  File "/opt/code/localstack/.venv/lib/python3.7/site-packages/urllib3/connection.py", line 157, in _new_conn
    (self._dns_host, self.port), self.timeout, **extra_kw
  File "/opt/code/localstack/.venv/lib/python3.7/site-packages/urllib3/util/connection.py", line 84, in create_connection
    raise err
  File "/opt/code/localstack/.venv/lib/python3.7/site-packages/urllib3/util/connection.py", line 74, in create_connection
    sock.connect(sa)
ConnectionRefusedError: [Errno 111] Connection refused

During handling of the above exception, another exception occurred:

Traceback (most recent call last):
  File "/opt/code/localstack/.venv/lib/python3.7/site-packages/urllib3/connectionpool.py", line 672, in urlopen
    chunked=chunked,
  File "/opt/code/localstack/.venv/lib/python3.7/site-packages/urllib3/connectionpool.py", line 387, in _make_request
    conn.request(method, url, **httplib_request_kw)
  File "/usr/lib/python3.7/http/client.py", line 1252, in request
    self._send_request(method, url, body, headers, encode_chunked)
  File "/usr/lib/python3.7/http/client.py", line 1298, in _send_request
    self.endheaders(body, encode_chunked=encode_chunked)
  File "/usr/lib/python3.7/http/client.py", line 1247, in endheaders
    self._send_output(message_body, encode_chunked=encode_chunked)
  File "/usr/lib/python3.7/http/client.py", line 1026, in _send_output
    self.send(msg)
  File "/usr/lib/python3.7/http/client.py", line 966, in send
    self.connect()
  File "/opt/code/localstack/.venv/lib/python3.7/site-packages/urllib3/connection.py", line 184, in connect
    conn = self._new_conn()
  File "/opt/code/localstack/.venv/lib/python3.7/site-packages/urllib3/connection.py", line 169, in _new_conn
    self, "Failed to establish a new connection: %s" % e
urllib3.exceptions.NewConnectionError: <urllib3.connection.HTTPConnection object at 0x7febf72f5290>: Failed to establish a new connection: [Errno 111] Connection refused

During handling of the above exception, another exception occurred:

Traceback (most recent call last):
  File "/opt/code/localstack/.venv/lib/python3.7/site-packages/requests/adapters.py", line 449, in send
    timeout=timeout
  File "/opt/code/localstack/.venv/lib/python3.7/site-packages/urllib3/connectionpool.py", line 720, in urlopen
    method, url, error=e, _pool=self, _stacktrace=sys.exc_info()[2]
  File "/opt/code/localstack/.venv/lib/python3.7/site-packages/urllib3/util/retry.py", line 436, in increment
    raise MaxRetryError(_pool, url, error or ResponseError(cause))
urllib3.exceptions.MaxRetryError: MyHTTPConnectionPool(host='localhost', port=4563): Max retries exceeded with url: /user-local-serverlessdeploymentbucket-7sai580wxc84?location (Caused by NewConnectionError('<urllib3.connection.HTTPConnection object at 0x7febf72f5290>: Failed to establish a new connection: [Errno 111] Connection refused'))

During handling of the above exception, another exception occurred:

Traceback (most recent call last):
  File "/opt/code/localstack/localstack/services/generic_proxy.py", line 284, in forward
    headers=forward_headers, stream=True)
  File "/opt/code/localstack/.venv/lib/python3.7/site-packages/requests/api.py", line 75, in get
    return request('get', url, params=params, **kwargs)
  File "/opt/code/localstack/.venv/lib/python3.7/site-packages/requests/api.py", line 60, in request
    return session.request(method=method, url=url, **kwargs)
  File "/opt/code/localstack/.venv/lib/python3.7/site-packages/requests/sessions.py", line 533, in request
    resp = self.send(prep, **send_kwargs)
  File "/opt/code/localstack/.venv/lib/python3.7/site-packages/requests/sessions.py", line 646, in send
    r = adapter.send(request, **kwargs)
  File "/opt/code/localstack/.venv/lib/python3.7/site-packages/requests/adapters.py", line 516, in send
    raise ConnectionError(e, request=request)
requests.exceptions.ConnectionError: MyHTTPConnectionPool(host='localhost', port=4563): Max retries exceeded with url: /user-local-serverlessdeploymentbucket-7sai580wxc84?location (Caused by NewConnectionError('<urllib3.connection.HTTPConnection object at 0x7febf72f5290>: Failed to establish a new connection: [Errno 111] Connection refused'))

Ready.
2020-02-13T21:21:29:WARNING:moto: No Moto CloudFormation support for AWS::S3::BucketPolicy
2020-02-13T21:21:30:WARNING:moto: No Moto CloudFormation support for AWS::S3::BucketPolicy
2020-02-13T21:21:34:WARNING:localstack.services.awslambda.lambda_api: Function not found: arn:aws:lambda:us-east-1:000000000000:function:createInvoice-local
2020-02-13T21:21:34:WARNING:localstack.services.awslambda.lambda_api: Function not found: arn:aws:lambda:us-east-1:000000000000:function:getInvoices-local
2020-02-13T21:21:34:WARNING:localstack.services.cloudformation.cloudformation_starter: Unable to extract id for resource IamRoleLambdaExecution: {'Role': {'Path': '/', 'RoleName': 'invoice-local-us-east-1-lambdaRole', 'RoleId': '5neebtll45itllya0elv', 'Arn': 'arn:aws:iam::000000000000:role/invoice-local-us-east-1-lambdaRole', 'CreateDate': datetime.datetime(2020, 2, 13, 21, 21, 34, 718000, tzinfo=tzlocal()), 'AssumeRolePolicyDocument': {'Version': '2012-10-17', 'Statement': [{'Effect': 'Allow', 'Principal': {'Service': ['lambda.amazonaws.com']}, 'Action': ['sts:AssumeRole']}]}, 'MaxSessionDuration': 3600}, 'ResponseMetadata': {'RequestId': '4a93ceee-9966-11e1-b624-b1aEXAMPLE7c', 'HTTPStatusCode': 200, 'HTTPHeaders': {'server': 'BaseHTTP/0.6 Python/3.7.5', 'date': 'Thu, 13 Feb 2020 21:21:34 GMT', 'content-type': 'text/html; charset=utf-8', 'content-length': '709', 'access-control-allow-origin': '*', 'access-control-allow-methods': 'HEAD,GET,PUT,POST,DELETE,OPTIONS,PATCH', 'access-control-allow-headers': 'authorization,content-type,content-md5,cache-control,x-amz-content-sha256,x-amz-date,x-amz-security-token,x-amz-user-agent,x-amz-target,x-amz-acl,x-amz-version-id,x-localstack-target,x-amz-tagging', 'access-control-expose-headers': 'x-amz-version-id'}, 'RetryAttempts': 0}}
2020-02-13T21:21:34:WARNING:localstack.services.awslambda.lambda_api: Function not found: arn:aws:lambda:us-east-1:000000000000:function:createInvoice-local
2020-02-13T21:21:34:WARNING:localstack.services.awslambda.lambda_api: Unknown error: Please note that Lambda mounts (bucket name "__local__") cannot be used with LAMBDA_REMOTE_DOCKER=1 Traceback (most recent call last):
  File "/opt/code/localstack/localstack/services/awslambda/lambda_api.py", line 768, in create_function
    result = set_function_code(func_details.code, lambda_name)
  File "/opt/code/localstack/localstack/services/awslambda/lambda_api.py", line 556, in set_function_code
    lambda_cwd = lambda_cwd or set_archive_code(code_passed, lambda_name)
  File "/opt/code/localstack/localstack/services/awslambda/lambda_api.py", line 511, in set_archive_code
    raise Exception(msg % BUCKET_MARKER_LOCAL)
Exception: Please note that Lambda mounts (bucket name "__local__") cannot be used with LAMBDA_REMOTE_DOCKER=1

2020-02-13T21:21:35:WARNING:localstack.services.awslambda.lambda_api: Unknown error: Please note that Lambda mounts (bucket name "__local__") cannot be used with LAMBDA_REMOTE_DOCKER=1 Traceback (most recent call last):
  File "/opt/code/localstack/localstack/services/awslambda/lambda_api.py", line 768, in create_function
    result = set_function_code(func_details.code, lambda_name)
  File "/opt/code/localstack/localstack/services/awslambda/lambda_api.py", line 556, in set_function_code
    lambda_cwd = lambda_cwd or set_archive_code(code_passed, lambda_name)
  File "/opt/code/localstack/localstack/services/awslambda/lambda_api.py", line 511, in set_archive_code
    raise Exception(msg % BUCKET_MARKER_LOCAL)
Exception: Please note that Lambda mounts (bucket name "__local__") cannot be used with LAMBDA_REMOTE_DOCKER=1

2020-02-13T21:21:35:WARNING:localstack.services.awslambda.lambda_api: Function not found: arn:aws:lambda:us-east-1:000000000000:function:createUser-local
2020-02-13T21:21:35:INFO:localstack.services.cloudformation.cloudformation_starter: Updating resource ID from 867790ff to frpsyewk91 (us-east-1)
2020-02-13T21:21:35:WARNING:localstack.services.cloudformation.cloudformation_starter: Unable to determine physical_resource_id for resource <class 'moto.apigateway.models.RestAPI'>
2020-02-13T21:21:35:INFO:localstack.services.cloudformation.cloudformation_starter: Updating resource ID from e770c5ca to rodkazo5zf (us-east-1)
2020-02-13T21:21:35:WARNING:localstack.services.cloudformation.cloudformation_starter: Unable to determine physical_resource_id for resource <class 'moto.apigateway.models.Resource'>
2020-02-13T21:21:35:WARNING:localstack.services.cloudformation.cloudformation_starter: Unable to extract id for resource IamRoleLambdaExecution: {'Role': {'Path': '/', 'RoleName': 'user-local-us-east-1-lambdaRole', 'RoleId': 'v7hneicmz8gcqeqc1gin', 'Arn': 'arn:aws:iam::000000000000:role/user-local-us-east-1-lambdaRole', 'CreateDate': datetime.datetime(2020, 2, 13, 21, 21, 35, 374000, tzinfo=tzlocal()), 'AssumeRolePolicyDocument': {'Version': '2012-10-17', 'Statement': [{'Effect': 'Allow', 'Principal': {'Service': ['lambda.amazonaws.com']}, 'Action': ['sts:AssumeRole']}]}, 'MaxSessionDuration': 3600}, 'ResponseMetadata': {'RequestId': '4a93ceee-9966-11e1-b624-b1aEXAMPLE7c', 'HTTPStatusCode': 200, 'HTTPHeaders': {'server': 'BaseHTTP/0.6 Python/3.7.5', 'date': 'Thu, 13 Feb 2020 21:21:35 GMT', 'content-type': 'text/html; charset=utf-8', 'content-length': '703', 'access-control-allow-origin': '*', 'access-control-allow-methods': 'HEAD,GET,PUT,POST,DELETE,OPTIONS,PATCH', 'access-control-allow-headers': 'authorization,content-type,content-md5,cache-control,x-amz-content-sha256,x-amz-date,x-amz-security-token,x-amz-user-agent,x-amz-target,x-amz-acl,x-amz-version-id,x-localstack-target,x-amz-tagging', 'access-control-expose-headers': 'x-amz-version-id'}, 'RetryAttempts': 0}}
2020-02-13T21:21:35:WARNING:moto: No Moto CloudFormation support for AWS::S3::BucketPolicy
2020-02-13T21:21:35:WARNING:localstack.services.awslambda.lambda_api: Function not found: arn:aws:lambda:us-east-1:000000000000:function:createUser-local
2020-02-13T21:21:35:WARNING:localstack.services.awslambda.lambda_api: Unknown error: Please note that Lambda mounts (bucket name "__local__") cannot be used with LAMBDA_REMOTE_DOCKER=1 Traceback (most recent call last):
  File "/opt/code/localstack/localstack/services/awslambda/lambda_api.py", line 768, in create_function
    result = set_function_code(func_details.code, lambda_name)
  File "/opt/code/localstack/localstack/services/awslambda/lambda_api.py", line 556, in set_function_code
    lambda_cwd = lambda_cwd or set_archive_code(code_passed, lambda_name)
  File "/opt/code/localstack/localstack/services/awslambda/lambda_api.py", line 511, in set_archive_code
    raise Exception(msg % BUCKET_MARKER_LOCAL)
Exception: Please note that Lambda mounts (bucket name "__local__") cannot be used with LAMBDA_REMOTE_DOCKER=1

2020-02-13T21:21:35:WARNING:localstack.services.awslambda.lambda_api: Unknown error: Please note that Lambda mounts (bucket name "__local__") cannot be used with LAMBDA_REMOTE_DOCKER=1 Traceback (most recent call last):
  File "/opt/code/localstack/localstack/services/awslambda/lambda_api.py", line 768, in create_function
    result = set_function_code(func_details.code, lambda_name)
  File "/opt/code/localstack/localstack/services/awslambda/lambda_api.py", line 556, in set_function_code
    lambda_cwd = lambda_cwd or set_archive_code(code_passed, lambda_name)
  File "/opt/code/localstack/localstack/services/awslambda/lambda_api.py", line 511, in set_archive_code
    raise Exception(msg % BUCKET_MARKER_LOCAL)
Exception: Please note that Lambda mounts (bucket name "__local__") cannot be used with LAMBDA_REMOTE_DOCKER=1

2020-02-13T21:21:36:WARNING:localstack.services.awslambda.lambda_api: Unknown error: Please note that Lambda mounts (bucket name "__local__") cannot be used with LAMBDA_REMOTE_DOCKER=1 Traceback (most recent call last):
  File "/opt/code/localstack/localstack/services/awslambda/lambda_api.py", line 768, in create_function
    result = set_function_code(func_details.code, lambda_name)
  File "/opt/code/localstack/localstack/services/awslambda/lambda_api.py", line 556, in set_function_code
    lambda_cwd = lambda_cwd or set_archive_code(code_passed, lambda_name)
  File "/opt/code/localstack/localstack/services/awslambda/lambda_api.py", line 511, in set_archive_code
    raise Exception(msg % BUCKET_MARKER_LOCAL)
Exception: Please note that Lambda mounts (bucket name "__local__") cannot be used with LAMBDA_REMOTE_DOCKER=1

2020-02-13T21:21:37:WARNING:localstack.services.awslambda.lambda_api: Unknown error: Please note that Lambda mounts (bucket name "__local__") cannot be used with LAMBDA_REMOTE_DOCKER=1 Traceback (most recent call last):
  File "/opt/code/localstack/localstack/services/awslambda/lambda_api.py", line 768, in create_function
    result = set_function_code(func_details.code, lambda_name)
  File "/opt/code/localstack/localstack/services/awslambda/lambda_api.py", line 556, in set_function_code
    lambda_cwd = lambda_cwd or set_archive_code(code_passed, lambda_name)
  File "/opt/code/localstack/localstack/services/awslambda/lambda_api.py", line 511, in set_archive_code
    raise Exception(msg % BUCKET_MARKER_LOCAL)
Exception: Please note that Lambda mounts (bucket name "__local__") cannot be used with LAMBDA_REMOTE_DOCKER=1

